<mujoco model="ant">
  <compiler inertiafromgeom="true" angle="degree" coordinate="local" />
  <option timestep="0.02" integrator="RK4" />
  <custom>
    <numeric name="init_qpos" data="0.0 0.0 0.55 1.0 0.0 0.0 0.0 0.0 1.0 0.0 -1.0 0.0 -1.0 0.0 1.0" />
  </custom>
  <default>
    <joint limited="true" armature="1" damping="1" />
    <geom condim="3" conaffinity="0" margin="0.01" friction="1 0.5 0.5" solref=".02 1" solimp=".8 .8 .01" rgba="0.8 0.6 0.4 1" density="5.0" />
  </default>
  <asset>
    <texture type="skybox" builtin="gradient" width="100" height="100" rgb1="1 1 1" rgb2="0 0 0" />
    <texture name="texgeom" type="cube" builtin="flat" mark="cross" width="127" height="1278" rgb1="0.8 0.6 0.4" rgb2="0.8 0.6 0.4" markrgb="1 1 1" random="0.01" />
    <texture name="texplane" type="2d" builtin="checker" rgb1="0.2 0.3 0.4" rgb2="0.1 0.2 0.3" width="100" height="100" />
    <material name='MatPlane' texture="texplane" shininess="1" texrepeat="60 60" specular="1"  reflectance="0.0" />
    <material name='geom' texture="texgeom" texuniform="true" />
  </asset>
  <worldbody>
    <light directional="true" cutoff="100" exponent="1" diffuse="1 1 1" specular=".1 .1 .1" pos="0 0 1.3" dir="-0 0 -1.3" />
    <geom name='floor' pos='0 0 0' size='40 40 40' type='plane' conaffinity='1' rgba='0.8 0.9 0.8 1' condim='3' material='MatPlane' />
      <site name='goal' pos="10 10 0" size="1 1 1" type="sphere" rgba='0.3 0.6 0.3 1'/>
        <site name='trap' pos="5 5 -0.9" size="3 1" type="cylinder" rgba=".6 .3 .3 1"/>

        <body name="torso" pos="0 0 0">
      <geom name="pointbody" type="sphere" size="0.5" pos="0 0 0.5" />
      <geom name="pointarrow" type="box" size="0.5 0.1 0.1" pos="0.6 0 0.5" />
      <joint name='ballx' type='slide' axis='1 0 0' pos='0 0 0' />
      <joint name='bally' type='slide' axis='0 1 0' pos='0 0 0' />
      <joint name='rot' type='hinge' axis='0 0 1' pos='0 0 0' limited="false" />
    </body>

  </worldbody>
  <actuator>
    <motor joint="hip_4" ctrlrange="-30.0 30.0" ctrllimited="true" />
    <motor joint="ankle_4" ctrlrange="-30.0 30.0" ctrllimited="true" />
    <motor joint="hip_1" ctrlrange="-30.0 30.0" ctrllimited="true" />
    <motor joint="ankle_1" ctrlrange="-30.0 30.0" ctrllimited="true" />
    <motor joint="hip_2" ctrlrange="-30.0 30.0" ctrllimited="true" />
    <motor joint="ankle_2" ctrlrange="-30.0 30.0" ctrllimited="true" />
    <motor joint="hip_3" ctrlrange="-30.0 30.0" ctrllimited="true" />
    <motor joint="ankle_3" ctrlrange="-30.0 30.0" ctrllimited="true" />
  </actuator>
</mujoco>
